Workbook

Sheet DoubleClubble
A1: CharltonWestHam | E1: =vlookup(F2,AwayFixtures!$B$1:$C$47,2,FALSE) -> 22-08-2026 | J1: CharltonWatford | N1: =vlookup(O2,AwayFixtures!$B$1:$C$47,2,FALSE) -> 17-10-2026 | S1: CharltonWestBrom | W1: =vlookup(X2,AwayFixtures!$B$1:$C$47,2,FALSE) -> 02-09-2026 | AB1: CharltonStoke | AF1: =vlookup(AG2,AwayFixtures!$B$1:$C$47,2,FALSE) -> 05-09-2026 | AK1: CharltonSouthampton | AO1: =vlookup(AP2,AwayFixtures!$B$1:$C$47,2,FALSE) -> 20-03-2027 | AT1: CharltonSheffUtd | AX1: =vlookup(AY2,AwayFixtures!$B$1:$C$47,2,FALSE) -> 30-01-2027 | BC1: CharltonBirmingham | BG1: =vlookup(BH2,AwayFixtures!$B$1:$C$47,2,FALSE) -> 17-03-2027 | BL1: CharltonBlackburn | BP1: =vlookup(BQ2,AwayFixtures!$B$1:$C$47,2,FALSE) -> 28-11-2026 | BU1: CharltonBolton | BY1: =vlookup(BZ2,AwayFixtures!$B$1:$C$47,2,FALSE) -> 26-01-2027 | CD1: CharltonBristolCity | CH1: =vlookup(CI2,AwayFixtures!$B$1:$C$47,2,FALSE) -> 27-02-2027 | CM1: CharltonBurnley | CQ1: =vlookup(CR2,AwayFixtures!$B$1:$C$47,2,FALSE) -> 13-10-2026 | CV1: CharltonCardiff | CZ1: =vlookup(DA2,AwayFixtures!$B$1:$C$47,2,FALSE) -> 19-09-2026 | DE1: CharltonDerby | DI1: =vlookup(DJ2,AwayFixtures!$B$1:$C$47,2,FALSE) -> 06-02-2027 | DN1: CharltonMillwall | DR1: =vlookup(DS2,AwayFixtures!$B$1:$C$47,2,FALSE) -> 19-12-2026 | DW1: CharltonLincoln | EA1: =vlookup(EB2,AwayFixtures!$B$1:$C$47,2,FALSE) -> 01-05-2027 | EF1: CharltonMiddlesbrough | EJ1: =vlookup(EK2,AwayFixtures!$B$1:$C$47,2,FALSE) -> 31-10-2026 | EO1: CharltonNorwich | ES1: =vlookup(ET2,AwayFixtures!$B$1:$C$47,2,FALSE) -> 29-12-2026 | EX1: CharltonPortsmouth | FB1: =vlookup(FC2,AwayFixtures!$B$1:$C$47,2,FALSE) -> 13-02-2027 | FG1: CharltonPreston | FK1: =vlookup(FL2,AwayFixtures!$B$1:$C$47,2,FALSE) -> 17-04-2027 | FP1: CharltonQPR | FT1: =vlookup(FU2,AwayFixtures!$B$1:$C$47,2,FALSE) -> 06-04-2027 | FY1: CharltonSwansea | GC1: =vlookup(GD2,AwayFixtures!$B$1:$C$47,2,FALSE) -> 01-01-2027 | GH1: CharltonWolves | GL1: =vlookup(GM2,AwayFixtures!$B$1:$C$47,2,FALSE) -> 21-11-2026 | GQ1: CharltonWrexham | GU1: =vlookup(GV2,AwayFixtures!$B$1:$C$47,2,FALSE) -> 08-12-2026 | GZ1: CharltonTottenham | HD1: 25-08-2026
C2: Charlton | F2: West Ham United | L2: Charlton Athletic | O2: Watford | U2: Charlton Athletic | X2: West Bromwich Albion | AD2: Charlton Athletic | AG2: Stoke City | AM2: Charlton Athletic | AP2: Southampton | AV2: Charlton Athletic | AY2: Sheffield United | BE2: Charlton Athletic | BH2: Birmingham City | BN2: Charlton Athletic | BQ2: Blackburn Rovers | BW2: Charlton Athletic | BZ2: Bolton Wanderers | CF2: Charlton Athletic | CI2: Bristol City | CO2: Charlton Athletic | CR2: Burnley | CX2: Charlton Athletic | DA2: Cardiff City | DG2: Charlton Athletic | DJ2: Derby County | DP2: Charlton Athletic | DS2: Millwall | DY2: Charlton Athletic | EB2: Lincoln City | EH2: Charlton Athletic | EK2: Middlesbrough | EQ2: Charlton Athletic | ET2: Norwich City | EZ2: Charlton Athletic | FC2: Portsmouth | FI2: Charlton Athletic | FL2: Preston North End | FR2: Charlton Athletic | FU2: Queens Park Rangers | GA2: Charlton Athletic | GD2: Swansea City | GJ2: Charlton Athletic | GM2: Wolverhampton Wanderers | GS2: Charlton Athletic | GV2: Wrexham | HB2: Charlton Athletic | HE2: Tottenham Hotspur
A3: Players | B3: Position | C3: Years | D3: Played | E3: Scored | F3: Years | G3: Played | H3: Scored | J3: Player | K3: Position | L3: Years | M3: Apps | N3: Goals | O3: Years | P3: Apps | Q3: Goals | S3: Player | T3: Position | U3: Years | V3: Apps | W3: Goals | X3: Years | Y3: Apps | Z3: Goals | AB3: Player | AC3: Position | AD3: Years | AE3: Apps | AF3: Goals | AG3: Years | AH3: Apps | AI3: Goals | AK3: Player | AL3: Position | AM3: Years | AN3: Apps | AO3: Goals | AP3: Years | AQ3: Apps | AR3: Goals | AT3: Player | AU3: Position | AV3: Years | AW3: Apps | AX3: Goals | AY3: Years | AZ3: Apps | BA3: Goals | BC3: Player | BD3: Position | BE3: Years | BF3: Apps | BG3: Goals | BH3: Years | BI3: Apps | BJ3: Goals | BL3: Player | BM3: Position | BN3: Years | BO3: Apps | BP3: Goals | BQ3: Years | BR3: Apps | BS3: Goals | BU3: Player | BV3: Position | BW3: Years | BX3: Apps | BY3: Goals | BZ3: Years | CA3: Apps | CB3: Goals | CD3: Player | CE3: Position | CF3: Years | CG3: Apps | CH3: Goals | CI3: Years | CJ3: Apps | CK3: Goals | CM3: Player | CO3: Years | CP3: Apps | CQ3: Goals | CR3: Years | CS3: Apps | CT3: Goals | CV3: Player | CW3: Position | CX3: Years | CY3: Apps | CZ3: Goals | DA3: Years | DB3: Apps | DC3: Goals | DE3: Player | DF3: Position | DG3: Years | DH3: Apps | DI3: Goals | DJ3: Years | DK3: Apps | DL3: Goals | DN3: Player | DO3: Position | DP3: Years | DQ3: Apps | DR3: Goals | DS3: Years | DT3: Apps | DU3: Goals | DW3: Player | DX3: Position | DY3: Years | DZ3: Apps | EA3: Goals | EB3: Years | EC3: Apps | ED3: Goals | EF3: Player | EG3: Position | EH3: Years | EI3: Apps | EJ3: Goals | EK3: Years | EL3: Apps | EM3: Goals | EO3: Player | EP3: Position | EQ3: Years | ER3: Apps | ES3: Goals | ET3: Years | EU3: Apps | EV3: Goals | EX3: Player | EY3: Position | EZ3: Years | FA3: Apps | FB3: Goals | FC3: Years | FD3: Apps | FE3: Goals | FG3: Player | FH3: Position | FI3: Years | FJ3: Apps | FK3: Goals | FL3: Years | FM3: Apps | FN3: Goals | FP3: Player | FQ3: Position | FR3: Years | FS3: Apps | FT3: Goals | FU3: Years | FV3: Apps | FW3: Goals | FY3: Player | FZ3: Position | GA3: Years | GB3: Apps | GC3: Goals | GD3: Years | GE3: Apps | GF3: Goals | GH3: Player | GI3: Position | GJ3: Years | GK3: Apps | GL3: Goals | GM3: Years | GN3: Apps | GO3: Goals | GQ3: Player | GR3: Position | GS3: Years | GT3: Apps | GU3: Goals | GV3: Years | GW3: Apps | GX3: Goals | GZ3: Player | HA3: Position | HB3: Years | HC3: Apps | HD3: Goals | HE3: Years | HF3: Apps | HG3: Goals
A4: Tal Ben Haim | B4: CB | C4: 2014-2015 | D4: 38 | E4: 0 | F4: 2010 | G4: 8 | H4: 0 | J4: James Abankwah | K4: CB, RB | L4: 2023 | M4: 3 | N4: 0 | O4: 2024-2025 | P4: 51 | Q4: 1 | S4: Krystian Bielik | T4: CDM, CB | U4: 2018 | V4: 31 | W4: 3 | X4: 2025 | Y4: 19 | Z4: 0 | AB4: Jay Bothroyd | AC4: ST | AD4: 2005 | AE4: 18 | AF4: 2 | AG4: 2007 | AH4: 4 | AI4: 0 | AK4: Joe Aribo | AL4: CM | AM4: 2016-2018 | AN4: 85 | AO4: 14 | AP4: 2022-2025 | AQ4: 109 | AR4: 9 | AT4: Marcus Bent | AU4: ST | AV4: 2005-2007 | AW4: 46 | AX4: 4 | AY4: 1999-2010 | AZ4: 59 | BA4: 20 | BC4: Darren Ambrose | BD4: CAM, RM, LM | BE4: 2005-2008 | BF4: 112 | BG4: 13 | BH4: 2012-2013 | BI4: 7 | BJ4: 0 | BL4: Amari'i Bell | BM4: CB, LB | BN4: 2025 | BO4: 35 | BP4: 0 | BQ4: 2017-2020 | BR4: 99 | BS4: 3 | BU4: Ben Alnwick | BV4: GK | BW4: 2013 | BX4: 10 | BY4: 0 | BZ4: 2016-2019 | CA4: 93 | CB4: 0 | CD4: Joe Anyinsah | CE4: ST | CF4: 2010 | CG4: 19 | CH4: 3 | CI4: 2004 | CJ4: 7 | CK4: 0 | CM4: Jóhann Berg Guðmundsson | CN4: LM, RM | CO4: 2014-2015 | CP4: 86 | CQ4: 17 | CR4: 2016-2024 | CS4: 223 | CT4: 15 | CV4: Ben Amos | CW4: GK | CX4: 2017-2020 | CY4: 97 | CZ4: 0 | DA4: 2016 | DB4: 16 | DC4: 0 | DE4: Darren Bent | DF4: ST | DG4: 2005-2006 | DH4: 68 | DI4: 31 | DJ4: 2014-2017 | DK4: 84 | DL4: 28 | DN4: Ben Amos | DO4: GK | DP4: 2017-2020 | DQ4: 97 | DR4: 0 | DS4: 2018 | DT4: 15 | DU4: 0 | DW4: Macauley Bonne | DX4: ST | DY4: 2019-2022 | DZ4: 55 | EA4: 14 | EB4: 2016 | EC4: 8 | ED4: 1 | EF4: Nicky Bailey | EG4: CM | EH4: 2008-2009 | EI4: 87 | EJ4: 25 | EK4: 2010-2012 | EL4: 99 | EM4: 4 | EO4: Ben Alnwick | EP4: GK | EQ4: 2013 | ER4: 10 | ES4: 0 | ET4: 2009 | EU4: 3 | EV4: 0 | EX4: Gassan Ahadme | EY4: ST | EZ4: 2024 | FA4: 22 | FB4: 4 | FC4: 2021 | FD4: 7 | FE4: 0 | FG4: Pawel Abbott | FH4: ST | FI4: 2010 | FJ4: 17 | FK4: 1 | FL4: 2002-2003 | FM4: 25 | FN4: 5 | FP4: Bradley Allen | FQ4: ST | FR4: 1995-1999 | FS4: 40 | FT4: 9 | FU4: 1992-1995 | FV4: 59 | FW4: 20 | FY4: Pawel Abbott | FZ4: ST | GA4: 2010 | GB4: 17 | GC4: 1 | GD4: 2006 | GE4: 18 | GF4: 1 | GH4: Marcus Bent | GI4: ST | GJ4: 2005-2007 | GK4: 46 | GL4: 4 | GM4: 2010 | GN4: 3 | GO4: 0 | GQ4: Joe Anyinsah | GR4: ST | GS4: 2010 | GT4: 19 | GU4: 3 | GV4: 2013 | GW4: 34 | GX4: 4 | GZ4: Ben Alnwick | HA4: GK | HB4: 2013 | HC4: 10 | HD4: 0 | HE4: 2009 | HF4: 1 | HG4: 0
A5: Mark Bowen | B5: LB | C5: 1997-1998 | D5: 42 | E5: 0 | F5: 1996 | G5: 17 | H5: 1 | J5: Dennis Bailey | K5: ST | L5: 1993 | M5: 4 | N5: 0 | O5: 1993 | P5: 8 | Q5: 4 | S5: David Button | T5: GK | U5: 2012 | V5: 5 | W5: 0 | X5: 2020-2022 | Y5: 34 | Z5: 0 | AB5: Deon Burton | AC5: ST | AD5: 2008-2009 | AE5: 59 | AF5: 18 | AG5: 2001 | AH5: 12 | AI5: 2 | AK5: Leon Best | AL5: ST | AM5: 2017 | AN5: 6 | AO5: 0 | AP5: 2004-2006 | AQ5: 11 | AR5: 4 | AT5: Tyler Bindon | AU5: CB | AV5: 2026- | AW5: 2* | AX5: 0* | AY5: 2026 | AZ5: 26 | BA5: 1 | BC5: Chuks Aneke | BD5: ST | BE5: 2019-2024 | BF5: 134 | BG5: 27 | BH5: 2021 | BI5: 21 | BJ5: 2 | BL5: Marcus Bent | BM5: ST | BN5: 2005-2007 | BO5: 46 | BP5: 4 | BQ5: 2000-2001 | BR5: 37 | BS5: 8 | BU5: Ben Amos | BV5: GK | BW5: 2017-2020 | BX5: 97 | BY5: 0 | BZ5: 2014-2016 | CA5: 53 | CB5: 0 | CD5: Tyreeq Bakinson | CE5: CM | CF5: 2023 | CG5: 15 | CH5: 1 | CI5: 2017-2021 | CJ5: 54 | CK5: 5 | CM5: André Bikey | CN5: CB | CO5: 2014 | CP5: 34 | CQ5: 1 | CR5: 2009-2011 | CS5: 70 | CT5: 3 | CV5: Harry Arter | CW5: CM | CX5: 2021 | CY5: 5 | CZ5: 0 | DA5: 2018 | DB5: 25 | DC5: 0 | DE5: Leon Best | DF5: ST | DG5: 2017 | DH5: 6 | DI5: 0 | DJ5: 2014 | DK5: 20 | DL5: 1 | DN5: Nicky Bailey | DO5: CM | DP5: 2008-2009 | DQ5: 87 | DR5: 25 | DS5: 2013-2014 | DT5: 36 | DU5: 1 | DW5: Conor Coventry | DX5: CM | DY5: 2023-2025 | DZ5: 106 | EA5: 1 | EB5: 2019 | EC5: 7 | ED5: 0 | EF5: Marcus Bent | EG5: ST | EH5: 2005-2007 | EI5: 46 | EJ5: 4 | EK5: 2009 | EL5: 7 | EM5: 0 | EO5: Mark Bowen | EP5: LB | EQ5: 1997-1998 | ER5: 42 | ES5: 0 | ET5: 1992-1995 | EU5: 156 | EV5: 11 | EX5: Millenic Alli | EY5: LW, RW | EZ5: 2026- | FA5: 4* | FB5: 0* | FC5: 2026 | FD5: 21 | FE5: 1 | FG5: Chuks Aneke | FH5: ST | FI5: 2019-2024 | FJ5: 134 | FK5: 27 | FL5: 2011 | FM5: 7 | FN5: 1 | FP5: Dennis Bailey | FQ5: ST | FR5: 1993 | FS5: 4 | FT5: 0 | FU5: 1992 | FV5: 15 | FW5: 1 | FY5: Federico Bessone | FZ5: LB | GA5: 2010 | GB5: 13 | GC5: 0 | GD5: 2008-2011 | GE5: 37 | GF5: 1 | GH5: Jay Bothroyd | GI5: ST | GJ5: 2005 | GK5: 18 | GL5: 2 | GM5: 2006-2007 | GN5: 55 | GO5: 12 | GQ5: Andrew Crofts | GR5: CM | GS5: 2016-2017 | GT5: 50 | GU5: 1 | GV5: 2008 | GW5: 16 | GX5: 1 | GZ5: Darren Bent | HA5: ST | HB5: 2005-2006 | HC5: 68 | HD5: 31 | HE5: 2007-2008 | HF5: 74 | HG5: 24
A6: Lee Bowyer | B6: CM | C6: 1993-1996 | D6: 46 | E6: 8 | F6: 2002-2008 | G6: 53 | H6: 4 | J6: Hameur Bouazza | K6: LM, RM | L6: 2008 | M6: 25 | N6: 4 | O6: 2003-2006 | P6: 83 | Q6: 8 | S6: Scott Carson | T6: GK | U6: 2006 | V6: 36 | W6: 0 | X6: 2008-2010 | Y6: 110 | Z6: 0 | AB6: Harry Clarke | AC6: CB, RB | AD6: 2025 | AE6: 19 | AF6: 0 | AG6: 2022 | AH6: 20 | AI6: 2 | AK6: James Bree | AL6: RB | AM6: 2025 | AN6: 22 | AO6: 2 | AP6: 2022-2025 | AQ6: 76 | AR6: 7 | AT6: Jamal Campbell-Ryce | AU6: RM | AV6: 2002-2003 | AW6: 3 | AX6: 0 | AY6: 2014-2015 | AZ6: 49 | BA6: 6 | BC6: Amari'i Bell | BD6: CB, LB | BE6: 2025 | BF6: 35 | BG6: 0 | BH6: 2013 | BI6: 1 | BJ6: 0 | BL6: Leon Best | BM6: ST | BN6: 2017 | BO6: 6 | BP6: 0 | BQ6: 2012-2013 | BR6: 14 | BS6: 2 | BU6: Rob Apter | BV6: RW, RWB | BW6: 2025 | BX6: 13 | BY6: 1 | BZ6: 2025 | CA6: 13 | CB6: 0 | CD6: André Bikey | CE6: CB | CF6: 2014 | CG6: 34 | CH6: 1 | CI6: 2011 | CJ6: 7 | CK6: 0 | CM6: Nathaniel Chalobah | CN6: CM | CO6: 2026- | CP6: 3* | CQ6: 0* | CR6: 2014-2015 | CS6: 4 | CT6: 0 | CV6: Mickey Bennett | CW6: MF | CX6: 1993-1995 | CY6: 24 | CZ6: 1 | DA6: 1996 | DB6: 14 | DC6: 1 | DE6: Krystian Bielik | DF6: CDM, CB | DG6: 2018 | DH6: 31 | DI6: 3 | DJ6: 2019-2021 | DK6: 53 | DL6: 3 | DN6: Federico Bessone | DO6: LB | DP6: 2010 | DQ6: 13 | DR6: 0 | DS6: 2013 | DT6: 2 | DU6: 0 | DW6: Tayo Edun | DX6: LB | DY6: 2023-2024 | DZ6: 31 | EA6: 0 | EB6: 2019-2021 | EC6: 55 | ED6: 3 | EF6: André Bikey | EG6: CB | EH6: 2014 | EI6: 34 | EJ6: 1 | EK6: 2012 | EL6: 33 | EM6: 1 | EO6: Andrew Crofts | EP6: CM | EQ6: 2016-2017 | ER6: 50 | ES6: 1 | ET6: 2010-2011 | EU6: 68 | EV6: 8 | EX6: Tal Ben Haim | EY6: CB | EZ6: 2014 | FA6: 38 | FB6: 0 | FC6: 2009-2011 | FD6: 55 | FE6: 0 | FG6: Joe Anyinsah | FH6: ST | FI6: 2010 | FJ6: 19 | FK6: 3 | FL6: 2006 | FM6: 3 | FN6: 0 | FP6: Tal Ben Haim | FQ6: CB | FR6: 2014 | FS6: 38 | FT6: 0 | FU6: 2012 | FV6: 3 | FW6: 0 | FY6: Conor Gallagher | FZ6: CM | GA6: 2019 | GB6: 26 | GC6: 6 | GD6: 2019 | GE6: 19 | GF6: 0 | GH6: Nathan Byrne | GI6: RB, RW | GJ6: 2016 | GK6: 17 | GL6: 1 | GM6: 2015 | GN6: 24 | GO6: 2 | GQ6: George Dobson | GR6: CM | GS6: 2021-2023 | GT6: 139 | GU6: 5 | GV6: 2024-2025 | GW6: 90 | GX6: 3 | GZ6: Gary Doherty | HA6: CB | HB6: 2010-2011 | HC6: 41 | HD6: 0 | HE6: 1999-2004 | HF6: 64 | HG6: 4
A7: Reece Burke | B7: CB | C7: 2025 | D7: 17 | E7: 1 | F7: 2014-2017 | G7: 9 | H7: 1 | J7: Nathaniel Chalobah | K7: CM | L7: 2026- | M7: 3* | N7: 0 | O7: 2012-2013, 2017-2021 | P7: 127 | Q7: 9 | S7: Nathaniel Chalobah | T7: CM | U7: 2026- | V7: 3* | W7: 0* | X7: 2022-2024 | Y7: 49 | Z7: 1 | AB7: Leon Cort | AC7: CB | AD7: 2011-2013 | AE7: 48 | AF7: 2 | AG7: 2007-2008 | AH7: 44 | AI7: 8 | AK7: Danny Butterfield | AL7: RB | AM7: 2008 | AN7: 12 | AO7: 0 | AP7: 2010-2011 | AQ7: 44 | AR7: 0 | AT7: Billy Clarke | AU7: ST, CAM | AV7: 2017-2018 | AW7: 23 | AX7: 2 | AY7: 2011 | AZ7: 5 | BA7: 1 | BC7: Marcus Bent | BD7: ST | BE7: 2005-2007 | BF7: 46 | BG7: 4 | BH7: 2008 | BI7: 33 | BJ7: 3 | BL7: Jay Bothroyd | BM7: ST | BN7: 2005 | BO7: 18 | BP7: 2 | BQ7: 2004 | BR7: 11 | BS7: 1 | BU7: Anthony Barness | BV7: LB | BW7: 1992-1999 | BX7: 101 | BY7: 3 | BZ7: 2000-2004 | CA7: 93 | CB7: 0 | CD7: Jamal Campbell-Ryce | CE7: RM | CF7: 2002-2003 | CG7: 3 | CH7: 0 | CI7: 2009-2011 | CJ7: 62 | CK7: 2 | CM7: Leon Cort | CN7: CB | CO7: 2011-2013 | CP7: 48 | CQ7: 2 | CR7: 2009-2010 | CS7: 19 | CT7: 0 | CV7: Omar Bogle | CW7: ST | CX7: 2020 | CY7: 17 | CZ7: 2 | DA7: 2017-2019 | DB7: 24 | DC7: 4 | DE7: Corey Blackett-Taylor | DF7: LW | DG7: 2021-2023 | DH7: 90 | DI7: 18 | DJ7: 2023-2025 | DK7: 35 | DL7: 1 | DN7: Hameur Bouazza | DO7: LM, RM | DP7: 2008 | DQ7: 25 | DR7: 4 | DS7: 2010-2011 | DT7: 38 | DU7: 3 | DW7: Lewis Fiorini | DX7: CAM | DY7: 2023 | DZ7: 5 | EA7: 0 | EB7: 2021 | EC7: 41 | ED7: 6 | EF7: Nathaniel Chalobah | EG7: CM | EH7: 2026- | EI7: 3* | EJ7: 0* | EK7: 2013-2014 | EL7: 19 | EM7: 1 | EO7: Gary Doherty | EP7: CB | EQ7: 2010-2011 | ER7: 41 | ES7: 0 | ET7: 2004-2009 | EU7: 202 | EV7: 11 | EX7: Paul Benson | EY7: ST | EZ7: 2010-2011 | FA7: 33 | FB7: 10 | FC7: 2012 | FD7: 7 | FE7: 2 | FG7: Patrick Bauer | FH7: CB | FI7: 2015-2018 | FJ7: 129 | FK7: 8 | FL7: 2019-2024 | FM7: 105 | FN7: 8 | FP7: Marcus Bent | FQ7: ST | FR7: 2005-2007 | FS7: 46 | FT7: 4 | FU7: 2009 | FV7: 3 | FW7: 0 | FY7: Mark Gower | FZ7: CM | GA7: 2012-2013 | GB7: 13 | GC7: 0 | GD7: 2008-2012 | GE7: 128 | GF7: 3 | GH7: Chem Campbell | GI7: RW, LW | GJ7: 2023 | GK7: 14 | GL7: 2 | GM7: 2019-2023 | GN7: 57 | GO7: 13 | GQ7: Elliot Lee | GR7: CAM | GS7: 2021 | GT7: 37 | GU7: 3 | GV7: 2022-2025 | GW7: 145 | GX7: 39 | GZ7: Conor Gallagher | HA7: CM | HB7: 2019 | HC7: 26 | HD7: 6 | HE7: 2025 | HF7: 18 | HG7: 1
A8: Carlton Cole | B8: ST | C8: 2003 | D8: 21 | E8: 4 | F8: 2006-2014 | G8: 261 | H8: 56 | J8: Lee Cook | K8: LM | L8: 2007-2011 | M8: 13 | N8: 0 | O8: 2000-2003 | P8: 59 | Q8: 7 | S8: Sam Field | T8: CM | U8: 2019 | V8: 18 | W8: 0 | X8: 2015-2020 | Y8: 56 | Z8: 2 | AB8: Jordan Cousins | AC8: CM, RB | AD8: 2013-2015 | AE8: 131 | AF8: 7 | AG8: 2019-2020 | AH8: 47 | AI8: 0 | AK8: Martin Cranie | AL8: RB | AM8: 2008 | AN8: 19 | AO8: 0 | AP8: 2004-2005 | AQ8: 14 | AR8: 0 | AT8: Harry Clarke | AU8: CB, RB | AV8: 2025 | AW8: 19 | AX8: 0 | AY8: 2024 | AZ8: 6 | BA8: 0 | BC8: Krystian Bielik | BD8: CDM, CB | BE8: 2018 | BF8: 31 | BG8: 3 | BH8: 2016-2025 | BI8: 122 | BJ8: 2 | BL8: Christian Dailly | BM8: CB | BN8: 2009-2010 | BO8: 76 | BP8: 1 | BQ8: 1998-2000 | BR8: 72 | BS8: 4 | BU8: Tal Ben Haim | BV8: CB | BW8: 2014 | BX8: 38 | BY8: 0 | BZ8: 2004-2006 | CA8: 95 | CB8: 1 | CD8: Jay Dasilva | CE8: LB | CF8: 2016-2017 | CG8: 51 | CH8: 0 | CI8: 2018-2022 | CJ8: 144 | CK8: 2 | CM8: Josh Cullen | CN8: CM | CO8: 2018-2019 | CP8: 63 | CQ8: 2 | CR8: 2022-2025 | CS8: 140 | CT8: 7 | CV8: Jay Bothroyd | CW8: ST | CX8: 2005 | CY8: 18 | CZ8: 2 | DA8: 2008-2010 | DB8: 116 | DC8: 41 | DE8: Deon Burton | DF8: ST | DG8: 2008-2009 | DH8: 59 | DI8: 18 | DJ8: 1997-2002 | DK8: 125 | DL8: 25 | DN8: Allan Campbell | DO8: CM | DP8: 2024 | DQ8: 14 | DR8: 0 | DS8: 2023 | DT8: 12 | DU8: 0 | DW8: Reeco Hackett-Fairchild | DX8: LW, ST | DY8: 2017-2018 | DZ8: 12 | EA8: 0 | EB8: 2023-2025 | EC8: 111 | ED8: 22 | EF8: Martin Cranie | EG8: CB, RB | EH8: 2008 | EI8: 19 | EJ8: 0 | EK8: 2017 | EL8: 9 | EM8: 0 | EO8: Akin Famewo | EP8: CB | EQ8: 2020-2021 | ER8: 61 | ES8: 1 | ET8: 2018-2020 | EU8: 12 | EV8: 1 | EX8: Omar Bogle | EY8: ST | EZ8: 2020 | FA8: 17 | FB8: 2 | FC8: 2018 | FD8: 12 | FE8: 5 | FG8: Leon Clarke | FH8: ST | FI8: 2011 | FJ8: 7 | FK8: 0 | FL8: 2010 | FM8: 6 | FN8: 1 | FP8: Leon Best | FQ8: ST | FR8: 2017 | FS8: 6 | FT8: 0 | FU8: 2004 | FV8: 5 | FW8: 0 | FY8: Ben Hamer | FZ8: GK | GA8: 2011-2013 | GB8: 114 | GC8: 0 | GD8: 2020-2021 | GE8: 23 | GF8: 0 | GH8: Leon Clarke | GI8: ST | GJ8: 2011 | GK8: 7 | GL8: 0 | GM8: 2004-2014 | GN8: 90 | GO8: 11 | GQ8: Harry Lennon | GR8: CB | GS8: 2013-2017 | GT8: 35 | GU8: 2 | GV8: 2021-2022 | GW8: 19 | GX8: 2 | GZ8: Chris Gunter | HA8: RB | HB8: 2020-2021 | HC8: 56 | HD8: 1 | HE8: 2007-2008 | HF8: 12 | HG8: 0
A9: Conor Coventry | B9: CM | C9: 2023-2025 | D9: 106 | E9: 1 | F9: 2017-2023 | G9: 75 | H9: 8 | J9: Chris Eagles | K9: RW, LW | L9: 2014 | M9: 15 | N9: 2 | O9: 2004-2005 | P9: 30 | Q9: 4 | S9: Conor Gallagher | T9: CM | U9: 2019 | V9: 26 | W9: 6 | X9: 2020 | Y9: 32 | Z9: 2 | AB9: Alfie Doughty | AC9: LB, LW | AD9: 2018-2020 | AE9: 40 | AF9: 3 | AG9: 2021 | AH9: 17 | AI9: 0 | AK9: Christian Dailly | AL9: CB | AM9: 2009-2010 | AN9: 76 | AO9: 1 | AP9: 2007 | AQ9: 11 | AR9: 0 | AT9: Leon Clarke | AU9: ST | AV9: 2011 | AW9: 7 | AX9: 0 | AY9: 2016-2019 | AZ9: 95 | BA9: 31 | BC9: Omar Bogle | BD9: ST | BE9: 2020 | BF9: 17 | BG9: 2 | BH9: 2018 | BI9: 16 | BJ9: 1 | BL9: Tayo Edun | BM9: LB | BN9: 2023-2024 | BO9: 31 | BP9: 0 | BQ9: 2021-2022 | BR9: 41 | BS9: 0 | BU9: Corey Blackett-Taylor | BV9: LW | BW9: 2021-2023 | BX9: 90 | BY9: 18 | BZ9: 2025 | CA9: 7 | CB9: 2 | CD9: Hogan Ephraim | CE9: LW | CF9: 2011 | CG9: 5 | CH9: 1 | CI9: 2011 | CJ9: 5 | CK9: 1 | CM9: Chris Eagles | CN9: RW, LW | CO9: 2014 | CP9: 15 | CQ9: 2 | CR9: 2008-2010 | CS9: 120 | CT9: 20 | CV9: Deon Burton | CW9: ST | CX9: 2008-2009 | CY9: 59 | CZ9: 18 | DA9: 1996 | DB9: 5 | DC9: 2 | DE9: Nathan Byrne | DF9: RB, RW | DG9: 2016 | DH9: 17 | DI9: 1 | DJ9: 2020-2021 | DK9: 82 | DL9: 0 | DN9: Alfie Doughty | DO9: LB, LW | DP9: 2018-2020 | DQ9: 40 | DR9: 3 | DS9: 2025 | DT9: 26 | DU9: 0 | DW9: Mark McCammon | DX9: ST | DY9: 1999 | DZ9: 4 | EA9: 0 | EB9: 2011-2012 | EC9: 8 | ED9: 2 | EF9: Anfernee Dijksteel | EG9: RB | EH9: 2016-2019 | EI9: 48 | EJ9: 1 | EK9: 2019-2024 | EL9: 170 | EM9: 3 | EO9: Sam Field | EP9: CM | EQ9: 2019 | ER9: 18 | ES9: 0 | ET9: 2025 | EU9: 15 | EV9: 0 | EX9: Deon Burton | EY9: ST | EZ9: 2008-2009 | FA9: 59 | FB9: 18 | FC9: 1993-2003 | FD9: 78 | FE9: 14 | FG9: Leon Cort | FH9: CB | FI9: 2011-2013 | FJ9: 48 | FK9: 2 | FL9: 2010 | FM9: 13 | FN9: 0 | FP9: Macauley Bonne | FQ9: ST | FR9: 2019-2022 | FS9: 55 | FT9: 14 | FU9: 2020-2022 | FV9: 44 | FW9: 3 | FY9: Leroy Lita | FZ9: ST | GA9: 2007 | GB9: 8 | GC9: 3 | GD9: 2011-2013 | GE9: 18 | GF9: 2 | GH9: Conor Coady | GI9: CB, CDM | GJ9: 2025 | GK9: 12 | GL9: 1 | GM9: 2015-2022 | GN9: 311 | GO9: 7 | GQ9: Izale McLeod | GR9: ST | GS9: 2007-2009 | GT9: 31 | GU9: 3 | GV9: 2016 | GW9: 15 | GX9: 1 | GZ9: Johnnie Jackson | HA9: LM/CM/LB | HB9: 2009-2017 | HC9: 256 | HD9: 52 | HE9: 2003-2005 | HF9: 20 | HG9: 1
A10: Josh Cullen | B10: CM | C10: 2018-2019 | D10: 63 | E10: 2 | F10: 2014-2020 | G10: 10 | H10: 1 | J10: Rob Elliot | K10: GK | L10: 2007-2011 | M10: 96 | N10: 0 | O10: 2020-2021 | P10: 1 | Q10: 0 | S10: Karlan Grant | T10: ST | U10: 2014-2018, 2026- | V10: 95* | W10: 20* | X10: 2020-2025 | Y10: 174 | Z10: 35 | AB10: Amdy Faye | AC10: CDM | AD10: 2006-2007 | AE10: 29 | AF10: 1 | AG10: 2008 | AH10: 21 | AI10: 0 | AK10: Jason Euell | AL10: ST | AM10: 2001-2011 | AN10: 150 | AO10: 34 | AP10: 2007-2008 | AQ10: 62 | AR10: 5 | AT10: Conor Coady | AU10: CB, CDM | AV10: 2025 | AW10: 12 | AX10: 1 | AY10: 2013 | AZ10: 39 | BA10: 5 | BC10: Hameur Bouazza | BD10: LM, RM | BE10: 2008 | BF10: 25 | BG10: 4 | BH10: 2008 | BI10: 16 | BJ10: 1 | BL10: Keith Gillespie | BM10: RM | BN10: 2008 | BO10: 6 | BP10: 0 | BQ10: 1998-2002 | BR10: 116 | BS10: 5 | BU10: Reece Burke | BV10: CB | BW10: 2025 | BX10: 17 | BY10: 1 | BZ10: 2017 | CA10: 26 | CB10: 1 | CD10: Ben Hamer | CE10: GK | CF10: 2011-2013 | CG10: 114 | CH10: 0 | CI10: 2015 | CJ10: 5 | CK10: 0 | CM10: Andy Gray | CN10: ST | CO10: 2007-2009 | CP10: 45 | CQ10: 9 | CR10: 2005-2007 | CS10: 70 | CT10: 29 | CV10: Alfie Doughty | CW10: LB, LW | CX10: 2018-2020 | CY10: 40 | CZ10: 3 | DA10: 2021 | DB10: 9 | DC10: 1 | DE10: Scott Carson | DF10: GK | DG10: 2006 | DH10: 36 | DI10: 0 | DJ10: 2015-2018 | DK10: 167 | DL10: 0 | DN10: Ricardo Fuller | DO10: ST | DP10: 2012 | DQ10: 31 | DR10: 5 | DS10: 2014 | DT10: 40 | DU10: 6 | DW10: Conor McGrandles | DX10: CM | DY10: 2022-2023 | DZ10: 16 | EA10: 1 | EB10: 2020-2025 | EC10: 184 | ED10: 9 | EF10: Jason Euell | EG10: ST | EH10: 2001-2011 | EI10: 150 | EJ10: 34 | EK10: 2006 | EL10: 17 | EM10: 0 | EO10: Onel Hernández | EP10: LW, RW | EQ10: 2025 | ER10: 6 | ES10: 0 | ET10: 2017-2024 | EU10: 210 | EV10: 15 | EX10: Martin Cranie | EY10: CB, RB | EZ10: 2008 | FA10: 19 | FB10: 0 | FC10: 2007 | FD10: 2 | FE10: 0 | FG10: Ricardo Fuller | FH10: ST | FI10: 2012 | FJ10: 31 | FK10: 5 | FL10: 2002-2004 | FM10: 58 | FN10: 27 | FP10: Gary Borrowdale | FQ10: LB | FR10: 2009 | FS10: 10 | FT10: 0 | FU10: 2009-2010 | FV10: 22 | FW10: 0 | FY10: Frank Nouble | FZ10: ST | GA10: 2010 | GB10: 9 | GC10: 1 | GD10: 2010 | GE10: 6 | GF10: 1 | GH10: Carlton Cole | GI10: ST | GJ10: 2003 | GK10: 21 | GL10: 4 | GM10: 2002 | GN10: 7 | GO10: 1 | GQ10: Eoghan O'Connell | GR10: CB | GS10: 2022 | GT10: 22 | GU10: 1 | GV10: 2022-2025 | GW10: 90 | GX10: 2 | GZ10: Paul Konchesky | HA10: LB/LM | HB10: 1997-2004 | HC10: 149 | HD10: 5 | HE10: 2003 | HF10: 12 | HG10: 0
A11: Christian Dailly | B11: CB | C11: 2009-2010 | D11: 76 | E11: 1 | F11: 2000-2006 | G11: 158 | H11: 2 | J11: Ben Hamer | K11: GK | L11: 2011-2013 | M11: 114 | N11: 0 | O11: 2022-2023 | P11: 22 | Q11: 0 | S11: Robert Hulse | T11: ST | U11: 2012 | V11: 15 | W11: 3 | X11: 2003-2004 | Y11: 38 | Z11: 10 | AB11: Jonathan Fortune | AC11: CB | AD11: 1999-2010 | AE11: 182 | AF11: 6 | AG11: 2006 | AH11: 14 | AI11: 1 | AK11: Ricardo Fuller | AL11: ST | AM11: 2012 | AN11: 31 | AO11: 5 | AP11: 2005 | AQ11: 30 | AR11: 9 | AT11: Martin Cranie | AU11: RB | AV11: 2008 | AW11: 19 | AX11: 0 | AY11: 2018 | AZ11: 16 | BA11: 0 | BC11: Lee Bowyer | BD11: CM, RM | BE11: 1993-1996 | BF11: 46 | BG11: 8 | BH11: 2008-2010 | BI11: 81 | BJ11: 10 | BL11: Matty Holmes | BM11: LM | BN11: 1997-1999 | BO11: 16 | BP11: 1 | BQ11: 1995 | BR11: 12 | BS11: 1 | BU11: Mason Burstow | BV11: ST | BW11: 2021 | BX11: 18 | BY11: 3 | BZ11: 2025 | CA11: 48 | CB11: 12 | CD11: Danny Haynes | CE11: ST | CF11: 2011-2012 | CG11: 34 | CH11: 9 | CI11: 2009-2010 | CJ11: 51 | CK11: 8 | CM11: Chris Iwelumo | CN11: ST | CO11: 2007 | CP11: 46 | CQ11: 10 | CR11: 2010 | CS11: 45 | CT11: 11 | CV11: Neil Etheridge | CW11: GK | CX11: 2014 | CY11: 5 | CZ11: 0 | DA11: 2017-2020 | DB11: 102 | DC11: 0 | DE11: Christian Dailly | DF11: CB | DG11: 2009-2010 | DH11: 76 | DI11: 1 | DJ11: 1996-1998 | DK11: 67 | DL11: 4 | DN11: Danny Haynes | DO11: ST | DP11: 2011-2012 | DQ11: 34 | DR11: 9 | DS11: 2006 | DT11: 5 | DU11: 2 | DW11: Alex Mitchell | DX11: CB | DY11: 2024-2025 | DZ11: 35 | EA11: 2 | EB11: 2023 | EC11: 38 | ED11: 1 | EF11: Jimmy Floyd Hasselbaink | EG11: ST | EH11: 2006 | EI11: 25 | EJ11: 2 | EK11: 2004-2005 | EL11: 78 | EM11: 29 | EO11: Andrew Hughes | EP11: CM, RB | EQ11: 2011-2013 | ER11: 28 | ES11: 0 | ET11: 2005-2006 | EU11: 72 | EV11: 2 | EX11: Christian Dailly | EY11: CB | EZ11: 2009-2010 | FA11: 76 | FB11: 1 | FC11: 2011 | FD11: 1 | FE11: 0 | FG11: André Green | FH11: LW, RW, ST | FI11: 2019 | FJ11: 14 | FK11: 2 | FL11: 2019 | FM11: 6 | FN11: 1 | FP11: Jay Bothroyd | FQ11: ST | FR11: 2005 | FS11: 18 | FT11: 2 | FU11: 2011-2012 | FV11: 25 | FW11: 3 | FY11: Darren Pratley | FZ11: CM | GA11: 2018-2020 | GB11: 107 | GC11: 5 | GD11: 2006-2010 | GE11: 177 | GF11: 26 | GH11: David Davis | GI11: CM | GJ11: 2019 | GK11: 5 | GL11: 0 | GM11: 2011-2013 | GN11: 53 | GO11: 0 | GQ11: Arthur Okonkwo | GR11: GK | GS11: 2026- | GT11: 3* | GU11: 0* | GV11: 2023-2026 | GW11: 121 | GX11: 0 | GZ11: Danny Murphy | HA11: CM | HB11: 2004-2005 | HC11: 56 | HD11: 7 | HE11: 2005-2006 | HF11: 25 | HG11: 1
A12: Paolo Di Canio | B12: ST | C12: 2003 | D12: 31 | E12: 4 | F12: 1998-2002 | G12: 122 | H12: 49 | J12: Chris Iwelumo | K12: ST | L12: 2007 | M12: 46 | N12: 10 | O12: 2011-2012 | P12: 46 | Q12: 4 | S12: Andy Hunt | T12: ST | U12: 1998-2000 | V12: 86 | W12: 34 | X12: 1992-1997 | Y12: 212 | Z12: 76 | AB12: Tariqe Fosu | AC12: LW, RW | AD12: 2017-2018 | AE12: 61 | AF12: 11 | AG12: 2022 | AH12: 20 | AI12: 0 | AK12: Neil Heaney | AL12: LW | AM12: 1997 | AN12: 6 | AO12: 0 | AP12: 1993-1996 | AQ12: 61 | AR12: 5 | AT12: Jonathan Fortune | AU12: CB | AV12: 1999-2010 | AW12: 182 | AX12: 6 | AY12: 2009 | AZ12: 5 | BA12: 1 | BC12: Juan Castillo | BD12: LB | BE12: 2021 | BF12: 2 | BG12: 0 | BH12: 2021 | BI12: 9 | BJ12: 1 | BL12: Francis Jeffers | BM12: ST | BN12: 2004 | BO12: 20 | BP12: 3 | BQ12: 2006 | BR12: 13 | BS12: 1 | BU12: Danny Butterfield | BV12: RB | BW12: 2008 | BX12: 12 | BY12: 0 | BZ12: 2012 | CA12: 6 | CB12: 0 | CD12: Stephen Henderson | CE12: GK | CF12: 2014-2021 | CG12: 59 | CH12: 0 | CI12: 2007-2009 | CJ12: 5 | CK12: 0 | CM12: Ian Maatsen | CN12: LB | CO12: 2020 | CP12: 35 | CQ12: 1 | CR12: 2022 | CS12: 42 | CT12: 4 | CV12: Jimmy Floyd Hasselbaink | CW12: ST | CX12: 2006 | CY12: 25 | CZ12: 2 | DA12: 2007 | DB12: 36 | DC12: 7 | DE12: Ben Hamer | DF12: GK | DG12: 2011-2013 | DH12: 114 | DI12: 0 | DJ12: 2019 | DK12: 27 | DL12: 0 | DN12: Robert Hulse | DO12: ST | DP12: 2012 | DQ12: 15 | DR12: 3 | DS12: 2012 | DT12: 11 | DU12: 0 | DW12: Dany N'Guessan | DX12: LM, RM | DY12: 2011 | DZ12: 7 | EA12: 4 | EB12: 2006-2008 | EC12: 91 | ED12: 16 | EF12: Alexander Gilbert | EG12: CM | EH12: 2024 | EI12: 12 | EJ12: 0 | EK12: 2023-2025 | EL12: 49 | EM12: 4 | EO12: Matt Jackson | EP12: CB | EQ12: 1995 | ER12: 8 | ES12: 0 | ET12: 1996-2000 | EU12: 161 | EV12: 6 | EX12: Amdy Faye | EY12: CDM | EZ12: 2006-2007 | FA12: 29 | FB12: 1 | FC12: 2003-2004 | FD12: 47 | FE12: 0 | FG12: Paul Hayes | FH12: ST | FI12: 2011 | FJ12: 19 | FK12: 3 | FL12: 2010 | FM12: 23 | FN12: 2 | FP12: Leon Clarke | FQ12: ST | FR12: 2011 | FS12: 7 | FT12: 0 | FU12: 2010 | FV12: 13 | FW12: 0 | FY12: Jonjo Shelvey | FZ12: CAM | GA12: 2007-2009 | GB12: 42 | GC12: 7 | GD12: 2013-2015 | GE12: 92 | GF12: 10 | GH12: Kevin Foley | GI12: CM | GJ12: 2016 | GK12: 18 | GL12: 0 | GM12: 2007-2013 | GN12: 193 | GO12: 5 | GZ12: Jonathan Obika | HA12: ST | HB12: 2012-2013 | HC12: 22 | HD12: 3 | HE12: 2008 | HF12: 2 | HG12: 0
A13: Alou Diarra | B13: CB, CM | C13: 2014-2015 | D13: 45 | E13: 1 | F13: 2012-2013 | G13: 6 | H13: 0 | J13: Johnnie Jackson | K13: LM, CM | L13: 2009-2017 | M13: 256 | N13: 52 | O13: 2004 | P13: 15 | Q13: 0 | S13: Dean Kiely | T13: GK | U13: 1999-2005 | V13: 222 | W13: 0 | X13: 2006-2009 | Y13: 80 | Z13: 0 | AB13: Morgan Fox | AC13: LB | AD13: 2013-2016 | AE13: 113 | AF13: 1 | AG13: 2020-2022 | AH13: 80 | AI13: 0 | AK13: Tahar El Khalej | AL13: CB | AM13: 2002 | AN13: 3 | AO13: 0 | AP13: 1999-2002 | AQ13: 58 | AR13: 3 | AT13: Simon Francis | AU13: RB | AV13: 2010 | AW13: 34 | AX13: 0 | AY13: 2003-2004 | AZ13: 11 | BA13: 0 | BC13: David Davis | BD13: CM | BE13: 2019 | BF13: 5 | BG13: 0 | BH13: 2014-2020 | BI13: 194 | BJ13: 11 | BL13: Thomas Kaminski | BM13: GK | BN13: 2025 | BO13: 37 | BP13: 0 | BQ13: 2020-2022 | BR13: 119 | BS13: 0 | BU13: Adam Chicksen | BV13: LB | BW13: 2016 | BX13: 22 | BY13: 2 | BZ13: 2019 | CA13: 17 | CB13: 0 | CD13: Chris Iwelumo | CE13: ST | CF13: 2007 | CG13: 46 | CH13: 10 | CI13: 2009 | CJ13: 7 | CK13: 2 | CM13: Jay McEveley | CN13: LB | CO13: 2008 | CP13: 6 | CQ13: 0 | CR13: 2003 | CS13: 4 | CT13: 0 | CV13: Karlan Grant | CW13: ST | CX13: 2014-2018, 2026- | CY13: 95* | CZ13: 20 | DA13: 2023 | DB13: 40 | DC13: 6 | DE13: Bryan Hughes | DF13: CM | DG13: 2004-2006 | DH13: 74 | DI13: 5 | DJ13: 2009 | DK13: 3 | DL13: 0 | DN13: Trésor Kandol | DO13: ST | DP13: 2008 | DQ13: 13 | DR13: 2 | DS13: 2008 | DT13: 18 | DU13: 8 | DW13: Jack Payne | DX13: CAM | DY13: 2022-2023 | DZ13: 50 | EA13: 6 | EB13: 2019 | EC13: 27 | ED13: 2 | EF13: Onel Hernández | EG13: LW, RW | EH13: 2025 | EI13: 6 | EJ13: 0 | EK13: 2021 | EL13: 18 | EM13: 1 | EO13: Jonatan Johansson | EP13: ST | EQ13: 2000-2005 | ER13: 148 | ES13: 27 | ET13: 2005 | EU13: 12 | EV13: 3 | EX13: Ricardo Fuller | EY13: ST | EZ13: 2012 | FA13: 31 | FB13: 5 | FC13: 2004 | FD13: 31 | FE13: 1 | FG13: Todd Kane | FH13: RB | FI13: 2022 | FJ13: 5 | FK13: 0 | FL13: 2012 | FM13: 3 | FN13: 0 | FP13: Lee Cook | FQ13: LW | FR13: 2007-2011 | FS13: 13 | FT13: 0 | FU13: 2002-2009 | FV13: 182 | FW13: 12 | FY13: Scott Sinclair | FZ13: LW, RW | GA13: 2007 | GB13: 3 | GC13: 0 | GD13: 2010-2012 | GE13: 82 | GF13: 28 | GH13: Emmanuel Frimpong | GI13: CDM | GJ13: 2012 | GK13: 6 | GL13: 0 | GM13: 2011 | GN13: 5 | GO13: 0 | GZ13: Scott Parker | HA13: CM | HB13: 1997-2003 | HC13: 128 | HD13: 9 | HE13: 2011-2012 | HF13: 56 | HG13: 0
A14: Matty Holmes | B14: LM | C14: 1997-1999 | D14: 16 | E14: 1 | F14: 1992-1994 | G14: 76 | H14: 4 | J14: Matt Jackson | K14: CB | L14: 1995 | M14: 8 | N14: 0 | O14: 2007 | P14: 6 | Q14: 0 | S14: Mark Kinsella | T14: CM | U14: 1996-2001 | V14: 208 | W14: 20 | X14: 2003 | Y14: 18 | Z14: 1 | AB14: Ricardo Fuller | AC14: ST | AD14: 2012 | AE14: 31 | AF14: 5 | AG14: 2006-2011 | AH14: 186 | AI14: 44 | AK14: Graeme Murty | AL14: RB | AM14: 2008 | AN14: 8 | AO14: 0 | AP14: 2009 | AQ14: 6 | AR14: 0 | AT14: Keith Gillespie | AU14: RM | AV14: 2008 | AW14: 6 | AX14: 0 | AY14: 2005-2008 | AZ14: 97 | BA14: 4 | BC14: Lyndon Dykes | BD14: ST | BE14: 2025 | BF14: 20 | BG14: 3 | BH14: 2024-2025 | BI14: 51 | BJ14: 5 | BL14: Todd Kane | BM14: RB | BN14: 2022 | BO14: 5 | BP14: 0 | BQ14: 2012-2013 | BR14: 41 | BS14: 2 | BU14: Josh Cullen | BV14: CM | BW14: 2018-2019 | BX14: 63 | BY14: 2 | BZ14: 2017 | CA14: 12 | CB14: 0 | CD14: Todd Kane | CE14: RB | CF14: 2022 | CG14: 5 | CH14: 0 | CI14: 2014 | CJ14: 7 | CK14: 0 | CM14: Nick Pope | CN14: GK | CO14: 2012-2015 | CP14: 38 | CQ14: 0 | CR14: 2016-2021 | CS14: 154 | CT14: 0 | CV14: Chris Gunter | CW14: RB | CX14: 2020-2021 | CY14: 56 | CZ14: 1 | DA14: 2006-2007 | DB14: 28 | DC14: 0 | DE14: Robert Hulse | DF14: ST | DG14: 2012 | DH14: 15 | DI14: 3 | DJ14: 2008-2010 | DK14: 82 | DL14: 28 | DN14: Kevin Lisbie | DO14: ST | DP14: 1996-2006 | DQ14: 155 | DR14: 16 | DS14: 2010 | DT14: 20 | DU14: 4 | DW14: Frazer Richardson | DX14: RB | DY14: 2009 | DZ14: 38 | EA14: 1 | EB14: 2003 | EC14: 2 | ED14: 0 | EF14: Carl Ikeme | EG14: GK | EH14: 2009 | EI14: 4 | EJ14: 0 | EK14: 2011 | EL14: 10 | EM14: 0 | EO14: Leroy Lita | EP14: ST | EQ14: 2007 | ER14: 8 | ES14: 3 | ET14: 2008 | EU14: 16 | EV14: 7 | EX14: André Green | EY14: RW, LW, ST | EZ14: 2019 | FA14: 14 | FB14: 2 | FC14: 2018 | FD14: 8 | FE14: 3 | FG14: Simon Makienok | FH14: ST | FI14: 2015 | FJ14: 37 | FK14: 5 | FL14: 2016 | FM14: 29 | FN14: 6 | FP14: Jordan Cousins | FQ14: CM | FR14: 2013-2015 | FS14: 131 | FT14: 7 | FU14: 2016-2018 | FV14: 70 | FW14: 1 | GH14: Greg Halford | GI14: RB | GJ14: 2007 | GK14: 16 | GL14: 2 | GM14: 2009-2010 | GN14: 17 | GO14: 0 | GZ14: Dean Parrett | HA14: CM | HB14: 2010 | HC14: 9 | HD14: 1 | HE14: 2008-2011 | HF14: 4 | HG14: 0
A15: Saša Ilić | B15: GK | C15: 1997-2000 | D15: 51 | E15: 0 | F15: 1999 | G15: 1 | H15: 0 | J15: Jason Lee | K15: ST | L15: 1996 | M15: 8 | N15: 3 | O15: 1997-1998 | P15: 37 | Q15: 11 | S15: Jonathan Leko | T15: ST | U15: 2019-2021 | V15: 48 | W15: 7 | X15: 2015-2019 | Y15: 41 | Z15: 3 | AB15: Chris Iwelumo | AC15: ST | AD15: 2007 | AE15: 46 | AF15: 10 | AG15: 1999-2003 | AH15: 84 | AI15: 15 | AK15: Dany N'Guessan | AL15: LW, ST | AM15: 2011 | AN15: 7 | AO15: 4 | AP15: 2010 | AQ15: 6 | AR15: 0 | AT15: Andy Gray | AU15: ST | AV15: 2007-2009 | AW15: 45 | AX15: 9 | AY15: 2003-2004 | AZ15: 57 | BA15: 24 | BC15: Neil Etheridge | BD15: GK | BE15: 2014 | BF15: 5 | BG15: 0 | BH15: 2020-2023 | BI15: 84 | BJ15: 0 | BL15: Jay McEveley | BM15: LB | BN15: 2008 | BO15: 6 | BP15: 0 | BQ15: 2002-2006 | BR15: 19 | BS15: 0 | BU15: Dorian Dervite | BV15: CB | BW15: 2012-2013 | BX15: 70 | BY15: 5 | BZ15: 2014-2017 | CA15: 99 | CB15: 2 | CD15: Jonathan Leko | CE15: ST, RW | CF15: 2019-2021 | CG15: 48 | CH15: 7 | CI15: 2017 | CJ15: 11 | CK15: 0 | CM15: Jonjo Shelvey | CN15: CAM | CO15: 2007-2009 | CP15: 42 | CQ15: 7 | CR15: 2024 | CS15: 4 | CT15: 0 | CV15: Greg Halford | CW15: RB | CX15: 2007 | CY15: 16 | CZ15: 2 | DA15: 2016-2017 | DB15: 33 | DC15: 1 | DE15: Johnnie Jackson | DF15: LM, CM | DG15: 2009-2017 | DH15: 256 | DI15: 52 | DJ15: 2005 | DK15: 6 | DL15: 0 | DN15: Lee Martin | DO15: LM, RM | DP15: 2010 | DQ15: 20 | DR15: 2 | DS15: 2013-2015 | DT15: 65 | DU15: 2 | DW15: Cameron Stewart | DX15: LW, RW | DY15: 2013 | DZ15: 18 | EA15: 3 | EB15: 2017 | EC15: 4 | ED15: 0 | EF15: Leroy Lita | EG15: ST | EH15: 2007 | EI15: 8 | EJ15: 3 | EK15: 2009-2010 | EL15: 78 | EM15: 20 | EO15: Conor McGrandles | EP15: CM | EQ15: 2022-2023 | ER15: 16 | ES15: 1 | ET15: 2014 | EU15: 1 | EV15: 0 | EX15: Reeco Hackett-Fairchild | EY15: LW, ST | EZ15: 2017-2018 | FA15: 12 | FB15: 0 | FC15: 2021-2022 | FD15: 68 | FE15: 10 | FG15: Stephy Mavididi | FH15: LW, ST | FI15: 2016-2017 | FJ15: 17 | FK15: 2 | FL15: 2017 | FM15: 11 | FN15: 0 | FP15: Martin Cranie | FQ15: CB, RB | FR15: 2008 | FS15: 19 | FT15: 0 | FU15: 2007 | FV15: 6 | FW15: 0 | GH15: Carl Ikeme | GI15: GK | GJ15: 2009 | GK15: 4 | GL15: 0 | GM15: 2008-2016 | GN15: 196 | GO15: 0 | GZ15: Chris Perry | HA15: CB | HB15: 2003-2005 | HC15: 76 | HD15: 3 | HE15: 1999-2002 | HF15: 124 | HG15: 4
A16: Carl Jenkinson | B16: RB | C16: 2010 | D16: 8 | E16: 0 | F16: 2014-2015 | G16: 58 | H16: 2 | J16: Marco Motta | K16: RB | L16: 2015 | M16: 12 | N16: 0 | O16: 2014 | P16: 9 | Q16: 0 | S16: Frank Nouble | T16: ST | U16: 2010 | V16: 9 | W16: 1 | X16: 2009 | Y16: 3 | Z16: 0 | AB16: Gavin Kilkenny | AC16: CM | AD16: 2022 | AE16: 8 | AF16: 0 | AG16: 2022 | AH16: 4 | AI16: 0 | AK16: Chris Perry | AL16: CB | AM16: 2003-2005 | AN16: 76 | AO16: 3 | AP16: 2007-2009 | AQ16: 58 | AR16: 2 | AT16: Greg Halford | AU16: RB | AV16: 2007 | AW16: 16 | AX16: 2 | AY16: 2008 | AZ16: 41 | BA16: 4 | BC16: Nicky Forster | BD16: ST | BE16: 2009 | BF16: 8 | BG16: 2 | BH16: 1996-1999 | BI16: 68 | BJ16: 11 | BL16: Danny Murphy | BM16: CM | BN16: 2004-2005 | BO16: 56 | BP16: 7 | BQ16: 2012 | BR16: 33 | BS16: 1 | BU16: Joe Dodoo | BV16: ST | BW16: 2017 | BX16: 6 | BY16: 1 | BZ16: 2019 | CA16: 25 | CB16: 4 | CD16: Leroy Lita | CE16: ST | CF16: 2007 | CG16: 8 | CH16: 3 | CI16: 2002-2004 | CJ16: 85 | CK16: 31 | CM16: Marvin Sordell | CN16: ST | CO16: 2013 | CP16: 31 | CQ16: 7 | CR16: 2014-2015 | CS16: 21 | CT16: 1 | CV16: Mark Hudson | CW16: CB | CX16: 2008 | CY16: 43 | CZ16: 3 | DA16: 2009-2014 | DB16: 144 | DC16: 11 | DE16: Paul Kitson | DF16: ST | DG16: 1999 | DH16: 6 | DI16: 1 | DJ16: 1992-1994 | DK16: 93 | DL16: 32 | DN16: Mark McCammon | DO16: ST | DP16: 1999 | DQ16: 4 | DR16: 0 | DS16: 2002-2004 | DT16: 14 | DU16: 2 | EF16: Danny Mills | EG16: RB | EH16: 1997-2007 | EI16: 64 | EJ16: 3 | EK16: 2003 | EL16: 28 | EM16: 0 | EO16: Leon McKenzie | EP16: ST | EQ16: 2009 | ER16: 12 | ES16: 0 | ET16: 2003-2005 | EU16: 75 | EV16: 20 | EX16: Greg Halford | EY16: RB | EZ16: 2007 | FA16: 16 | FB16: 2 | FC16: 2010-2011 | FD16: 75 | FE16: 12 | FG16: Paddy McCarthy | FH16: CB | FI16: 2007 | FJ16: 29 | FK16: 2 | FL16: 2015 | FM16: 1 | FN16: 0 | FP16: Lyndon Dykes | FQ16: ST | FR16: 2025 | FS16: 20 | FT16: 3 | FU16: 2020-2024 | FV16: 165 | FW16: 37 | GH16: Chris Iwelumo | GI16: ST | GJ16: 2007 | GK16: 46 | GL16: 10 | GM16: 2008-2009 | GN16: 46 | GO16: 14 | GZ16: Andy Reid | HA16: CM | HB16: 2006-2007 | HC16: 38 | HD16: 8 | HE16: 2004-2005 | HF16: 26 | HG16: 1
A17: Roger Johnson | B17: CB | C17: 2014-2016 | D17: 23 | E17: 0 | F17: 2013 | G17: 4 | H17: 0 | J17: Chris Powell | K17: LB | L17: 1998-2007 | M17: 244 | N17: 2 | O17: 2006 | P17: 15 | Q17: 0 | S17: Chris Perry | T17: CB | U17: 2003-2005 | V17: 76 | W17: 3 | X17: 2006 | Y17: 23 | Z17: 0 | AB17: Lee Martin | AC17: LM, RM | AD17: 2010 | AE17: 20 | AF17: 2 | AG17: 2006 | AH17: 13 | AI17: 1 | AK17: Kayne Ramsey | AL17: RB, CB | AM17: 2023-2025 | AN17: 77 | AO17: 1 | AP17: 2018-2022 | AQ17: 38 | AR17: 0 | AT17: Ricky Holmes | AU17: RM | AV17: 2016-2017 | AW17: 62 | AX17: 19 | AY17: 2017 | AZ17: 5 | BA17: 0 | BC17: Greg Halford | BD17: RB | BE17: 2007 | BF17: 16 | BG17: 2 | BH17: 2015 | BI17: 3 | BJ17: 0 | BL17: Jack Payne | BM17: CAM | BN17: 2022-2023 | BO17: 50 | BP17: 6 | BQ17: 2017 | BR17: 18 | BS17: 1 | BU17: Chris Eagles | BV17: LW, RW | BW17: 2014 | BX17: 15 | BY17: 2 | BZ17: 2011-2013 | CA17: 93 | CB17: 17 | CD17: Adam Matthews | CE17: RB | CF17: 2019-2021 | CG17: 85 | CH17: 0 | CI17: 2015-2016 | CJ17: 23 | CK17: 0 | CM17: Dale Stephens | CN17: CM | CO17: 2011-2013 | CP17: 84 | CQ17: 9 | CR17: 2020-2021 | CS17: 16 | CT17: 0 | CV17: Roger Johnson | CW17: CB | CX17: 2014-2016 | CY17: 23 | CZ17: 0 | DA17: 2006-2008 | DB17: 119 | DC17: 12 | DE17: Joe Ledley | DF17: CM | DG17: 2019 | DH17: 1 | DI17: 0 | DJ17: 2017-2018 | DK17: 30 | DL17: 2 | DN17: Izale McLeod | DO17: ST | DP17: 2007-2009 | DQ17: 31 | DR17: 3 | DS17: 2008 | DT17: 7 | DU17: 2 | EF17: Robbie Mustoe | EG17: CM | EH17: 2002 | EI17: 6 | EJ17: 0 | EK17: 1992-2001 | EL17: 294 | EM17: 19 | EO17: Danny Mills | EP17: RB | EQ17: 1997-2007 | ER17: 64 | ES17: 3 | ET17: 1995-1997 | EU17: 66 | EV17: 0 | EX17: Stephen Henderson | EY17: GK | EZ17: 2014-2021 | FA17: 59 | FB17: 0 | FC17: 2011-2017 | FD17: 26 | FE17: 0 | FG17: Alan McCormack | FH17: CM | FI17: 2010 | FJ17: 24 | FK17: 1 | FL17: 2003-2004 | FM17: 8 | FN17: 0 | FP17: Hogan Ephraim | FQ17: LW | FR17: 2011 | FS17: 5 | FT17: 1 | FU17: 2007-2011 | FV17: 108 | FW17: 7 | GH17: Roger Johnson | GI17: CB | GJ17: 2014-2016 | GK17: 23 | GL17: 0 | GM17: 2011-2012 | GN17: 69 | GO17: 2 | GZ17: Kevin Scott | HA17: CB | HB17: 1996 | HC17: 4 | HD17: 0 | HE17: 1993-1995 | HF17: 18 | HG17: 1
A18: Steve Jones | B18: RW | C18: 1996-1999 | D18: 53 | E18: 8 | F18: 1992-1996 | G18: 24 | H18: 4 | J18: Sam Sodje | K18: CB | L18: 2007-2009 | M18: 54 | N18: 7 | O18: 2008 | P18: 1 | Q18: 0 | S18: Scott Sinclair | T18: LW | U18: 2007 | V18: 3 | W18: 0 | X18: 2013 | Y18: 8 | Z18: 0 | AB18: Jesurun Rak Sakyi | AC18: RW | AD18: 2022 | AE18: 49 | AF18: 15 | AG18: 2025 | AH18: 16 | AI18: 3 | AK18: Ben Reeves | AL18: CM | AM18: 2017-2018 | AN18: 61 | AO18: 9 | AP18: 2011-2025 | AQ18: 11 | AR18: 0 | AT18: Robert Hulse | AU18: ST | AV18: 2012 | AW18: 15 | AX18: 3 | AY18: 2006-2007 | AZ18: 50 | BA18: 8 | BC18: Onel Hernández | BD18: LW, RW | BE18: 2025 | BF18: 6 | BG18: 0 | BH18: 2021 | BI18: 22 | BJ18: 3 | BL18: Joe Rankin-Costello | BM18: CM, RB | BN18: 2025 | BO18: 26 | BP18: 2 | BQ18: 2017-2024 | BR18: 168 | BS18: 15 | BU18: Mark Fish | BV18: CB | BW18: 2000-2004 | BX18: 102 | BY18: 3 | BZ18: 1997-2000 | CA18: 103 | CB18: 3 | CD18: Mark McCammon | CE18: ST | CF18: 1999 | CG18: 4 | CH18: 0 | CI18: 2005 | CJ18: 11 | CK18: 4 | CM18: Cameron Stewart | CN18: LW, RW | CO18: 2013 | CP18: 18 | CQ18: 3 | CR18: 2012 | CS18: 9 | CT18: 0 | CV18: Joe Ledley | CW18: CM | CX18: 2019 | CY18: 1 | CZ18: 0 | DA18: 2004-2009 | DB18: 226 | DC18: 26 | DE18: Rob Lee | DF18: CM | DG18: 1992 | DH18: 7 | DI18: 1 | DJ18: 2001-2002 | DK18: 48 | DL18: 2 | DN18: Danny McNamara | DO18: RB | DP18: 2026- | DQ18: 5 | DR18: 0 | DS18: 2018-2026 | DT18: 166 | DU18: 2 | EF18: Darren Randolph | EG18: GK | EH18: 2006-2009 | EI18: 14 | EJ18: 0 | EK18: 2017-2019 | EL18: 110 | EM18: 0 | EO18: Dave Mooney | EP18: ST | EQ18: 2009 | ER18: 28 | ES18: 5 | ET18: 2008 | EU18: 9 | EV18: 3 | EX18: Danny Hollands | EY18: CM | EZ18: 2011-2012 | FA18: 57 | FB18: 7 | FC18: 2013-2015 | FD18: 92 | FE18: 8 | FG18: Jay McEveley | FH18: LB | FI18: 2008 | FJ18: 6 | FK18: 0 | FL18: 2008 | FM18: 7 | FN18: 0 | FP18: Sam Field | FQ18: CM | FR18: 2019 | FS18: 18 | FT18: 0 | FU18: 2020-2025 | FV18: 198 | FW18: 12 | GH18: Eggert Jónsson | GI18: CDM | GJ18: 2012 | GK18: 2 | GL18: 0 | GM18: 2011-2012 | GN18: 4 | GO18: 0 | GZ18: Ben Thatcher | HA18: LB/LM | HB18: 2006-2007 | HC18: 22 | HD18: 0 | HE18: 2000-2002 | HF18: 36 | HG18: 0
A19: Paul Kitson | B19: ST | C19: 1999 | D19: 6 | E19: 1 | F19: 1996-2001 | G19: 66 | H19: 19 | J19: Marvin Sordell | K19: ST | L19: 2013 | M19: 31 | N19: 7 | O19: 2009-2011 | P19: 75 | Q19: 21 | S19: Sam Sodje | T19: CB | U19: 2007-2009 | V19: 54 | W19: 7 | X19: 2006 | Y19: 7 | Z19: 1 | AB19: Frazer Richardson | AC19: RB | AD19: 2009 | AE19: 38 | AF19: 1 | AG19: 2002-2003 | AH19: 13 | AI19: 1 | AK19: Frazer Richardson | AL19: RB | AM19: 2009 | AN19: 38 | AO19: 1 | AP19: 2010-2012 | AQ19: 60 | AR19: 0 | AT19: Carl Ikeme | AU19: GK | AV19: 2009 | AW19: 4 | AX19: 0 | AY19: 2009 | AZ19: 2 | BA19: 0 | BC19: Bryan Hughes | BD19: CM | BE19: 2004-2006 | BF19: 74 | BG19: 5 | BH19: 1996-2003 | BI19: 248 | BJ19: 34 | BL19: Cameron Stewart | BM19: LW, RW | BN19: 2013 | BO19: 18 | BP19: 3 | BQ19: 2012 | BR19: 7 | BS19: 0 | BU19: Claus Jensen | BV19: CM | BW19: 2000-2003 | BX19: 122 | BY19: 16 | BZ19: 1998-1999 | CA19: 86 | CB19: 8 | CD19: Osei Sankofa | CE19: CB | CF19: 2002-2007 | CG19: 15 | CH19: 0 | CI19: 2005 | CJ19: 8 | CK19: 0 | CM19: Andy Todd | CN19: CB | CO19: 1999-2001 | CP19: 40 | CQ19: 1 | CR19: 2003 | CS19: 7 | CT19: 0 | CV19: Josh Magennis | CW19: ST | CX19: 2016-2017 | CY19: 85 | CZ19: 20 | DA19: 2009 | DB19: 9 | DC19: 0 | DE19: Kevin Lisbie | DF19: ST | DG19: 1996-2006 | DH19: 155 | DI19: 16 | DJ19: 2005 | DK19: 13 | DL19: 2 | DN19: Alex Mitchell | DO19: CB | DP19: 2024-2025 | DQ19: 35 | DR19: 2 | DS19: 2021 | DT19: 1 | DU19: 0 | EF19: Frazer Richardson | EG19: RB | EH19: 2009 | EI19: 38 | EJ19: 1 | EK19: 2013 | EL19: 11 | EM19: 0 | EO19: Elliot Omozusi | EP19: RB | EQ19: 2009 | ER19: 9 | ES19: 0 | ET19: 2008 | EU19: 21 | EV19: 0 | EX19: Ricky Holmes | EY19: RM | EZ19: 2016-2017 | FA19: 62 | FB19: 19 | FC19: 2013-2014 | FD19: 56 | FE19: 2 | FG19: Aiden McGeady | FH19: LW, RW | FI19: 2019 | FJ19: 10 | FK19: 0 | FL19: 2016 | FM19: 35 | FN19: 8 | FP19: Morgan Fox | FQ19: LB | FR19: 2013-2016 | FS19: 113 | FT19: 1 | FU19: 2023-2024 | FV19: 48 | FW19: 2 | GH19: Shaun Newton | GI19: RM | GJ19: 1992-2000 | GK19: 240 | GL19: 20 | GM19: 2001-2003 | GN19: 106 | GO19: 11 | GZ19: Miloš Veljković | HA19: CB | HB19: 2014 | HC19: 3 | HD19: 0 | HE19: 2013 | HF19: 2 | HG19: 0
A20: Paul Konchesky | B20: LB | C20: 1997-2004 | D20: 149 | E20: 5 | F20: 2005-2006 | G20: 61 | H20: 1 | J20: Matthew Spring | K20: CM | L20: 2008-2009 | M20: 25 | N20: 2 | O20: 2005-2006 | P20: 45 | Q20: 8 | S20: Jerome Thomas | T20: LW | U20: 2003-2008 | V20: 103 | W20: 7 | X20: 2009-2012 | Y20: 99 | Z20: 11 | AB20: Darel Russell | AC20: CDM | AD20: 2011 | AE20: 11 | AF20: 2 | AG20: 2003-2006 | AH20: 171 | AI20: 16 | AK20: Danny Seaborne | AL20: CB | AM20: 2012 | AN20: 7 | AO20: 0 | AP20: 2009-2011 | AQ20: 44 | AR20: 0 | AT20: Lee Martin | AU20: RM, LM | AV20: 2010 | AW20: 20 | AX20: 2 | AY20: 2007 | AZ20: 6 | BA20: 0 | BC20: Matt Jackson | BD20: CB | BE20: 1995 | BF20: 8 | BG20: 0 | BH20: 1996 | BI20: 10 | BJ20: 0 | BL20: Andy Todd | BM20: CB, RB | BN20: 1999-2001 | BO20: 40 | BP20: 1 | BQ20: 2002-2006 | BR20: 92 | BS20: 4 | BU20: Marcus Maddison | BV20: RW, LW | BW20: 2020 | BX20: 9 | BY20: 1 | BZ20: 2020 | CA20: 10 | CB20: 0 | CD20: Steven Sessegnon | CE20: RB, LB | CF20: 2022 | CG20: 38 | CH20: 2 | CI20: 2020 | CJ20: 18 | CK20: 0 | CM20: Fredrik Ulvestad | CN20: CM | CO20: 2016 | CP20: 29 | CQ20: 1 | CR20: 2014-2017 | CS20: 10 | CT20: 0 | CV20: Adam Matthews | CW20: RB | CX20: 2019-2021 | CY20: 85 | CZ20: 0 | DA20: 2009-2010 | DB20: 40 | DC20: 1 | DE20: Jay McEveley | DF20: LB | DG20: 2008 | DH20: 6 | DI20: 0 | DJ20: 2006-2009 | DK20: 92 | DL20: 4 | DN20: Dany N'Guessan | DO20: LM, RM | DP20: 2011 | DQ20: 7 | DR20: 4 | DS20: 2011-2013 | DT20: 29 | DU20: 2 | EF20: Ben Roberts | EG20: GK | EH20: 2002 | EI20: 1 | EJ20: 0 | EK20: 1993-1997 | EL20: 16 | EM20: 0 | EO20: Scott Parker | EP20: CM | EQ20: 1997-2003 | ER20: 128 | ES20: 9 | ET20: 2000 | EU20: 6 | EV20: 1 | EX20: Tareiq Holmes-Dennis | EY20: LB | EZ20: 2015-2016 | FA20: 14 | FB20: 0 | FC20: 2017 | FD20: 1 | FE20: 0 | FG20: Liam Millar | FH20: LW | FI20: 2020 | FJ20: 27 | FK20: 3 | FL20: 2023 | FM20: 36 | FN20: 5 | FP20: Ben Hamer | FQ20: GK | FR20: 2011-2013 | FS20: 114 | FT20: 0 | FU20: 2025 | FV20: 7 | FW20: 0 | GH20: Frank Nouble | GI20: ST | GJ20: 2010 | GK20: 9 | GL20: 1 | GM20: 2012 | GN20: 2 | GO20: 0 | GZ20: Luke Young | HA20: RB | HB20: 2001-2006 | HC20: 187 | HD20: 4 | HE20: 1998-2000 | HF20: 61 | HG20: 0
A21: Elliot Lee | B21: CAM | C21: 2021 | D21: 37 | E21: 3 | F21: 2013-2015 | G21: 2 | H21: 0 | J21: Toby Stevenson | K21: LB | L21: 2018-2019 | M21: 7 | N21: 1 | O21: 2020 | P21: 2 | Q21: 0 | S21: Ben Watson | T21: CM | U21: 2020-2021 | V21: 40 | W21: 1 | X21: 2009 | Y21: 7 | Z21: 1 | AB21: Tom Soares | AC21: CM | AD21: 2008 | AE21: 11 | AF21: 1 | AG21: 2008 | AH21: 7 | AI21: 0 | AK21: Thierry Small | AL21: LWB, RWB | AM21: 2023-2024 | AN21: 57 | AO21: 3 | AP21: 2021-2022 | AQ21: 22 | AR21: 4 | AT21: Paddy McCarthy | AU21: CB | AV21: 2007 | AW21: 29 | AX21: 2 | AY21: 2014 | AZ21: 11 | BA21: 1 | BC21: Carl Jenkinson | BD21: RB | BE21: 2010 | BF21: 8 | BG21: 0 | BH21: 2017 | BI21: 9 | BJ21: 0 | BL21: Luke Varney | BM21: ST | BN21: 2007-2008 | BO21: 57 | BP21: 10 | BQ21: 2013-2014 | BR21: 26 | BS21: 0 | BU21: Josh Magennis | BV21: ST | BW21: 2016-2017 | BX21: 85 | BY21: 20 | BZ21: 2018 | CA21: 45 | CB21: 6 | CD21: Scott Wagstaff | CE21: RW | CF21: 2007-2012 | CG21: 118 | CH21: 18 | CI21: 2013-2015 | CJ21: 78 | CK21: 8 | CM21: Rhys Williams | CN21: CB | CO21: 2015 | CP21: 4 | CQ21: 0 | CR21: 2008 | CS21: 16 | CT21: 0 | CV21: Conor McAleny | CW21: LW | CX21: 2015 | CY21: 9 | CZ21: 0 | DA21: 2014 | DB21: 8 | DC21: 2 | DE21: Izale McLeod | DF21: ST | DG21: 2007-2009 | DH21: 31 | DI21: 3 | DJ21: 2002-2003 | DK21: 39 | DL21: 4 | DN21: Jonathan Obika | DO21: ST | DP21: 2012-2013 | DQ21: 22 | DR21: 3 | DS21: 2009 | DT21: 12 | DU21: 2 | EF21: Andy Todd | EG21: CB | EH21: 1999-2001 | EI21: 40 | EJ21: 1 | EK21: 1993-1994 | EL21: 8 | EM21: 0 | EO21: Lee Power | EP21: ST | EQ21: 1992 | ER21: 5 | ES21: 0 | ET21: 1992-1993 | EU21: 25 | EV21: 6 | EX21: Hermann Hreiðarsson | EY21: LB | EZ21: 2003-2006 | FA21: 132 | FB21: 3 | FC21: 2007-2011 | FD21: 105 | FE21: 8 | FG21: Kevin Nicholls | FH21: RM | FI21: 1995-1999 | FJ21: 12 | FK21: 1 | FL21: 2007 | FM21: 18 | FN21: 0 | FP21: Tomer Hemed | FQ21: ST | FR21: 2019 | FS21: 19 | FT21: 0 | FU21: 2018 | FV21: 29 | FW21: 7 | GH21: Kyel Reid | GI21: LW | GJ21: 2009-2010 | GK21: 49 | GL21: 5 | GM21: 2008 | GN21: 8 | GO21: 1
A22: Rob Lee | B22: CM | C22: 1992 | D22: 7 | E22: 1 | F22: 2003 | G22: 16 | H22: 0 | J22: Darren Ward | K22: CB | L22: 2008 | M22: 16 | N22: 0 | O22: 1995-2008 | P22: 68 | Q22: 3 | AK22: Dale Stephens | AL22: CM | AM22: 2011-2013 | AN22: 84 | AO22: 9 | AP22: 2010 | AQ22: 6 | AR22: 0 | AT22: Jay McEveley | AU22: LB | AV22: 2008 | AW22: 6 | AX22: 0 | AY22: 2014-2015 | AZ22: 83 | BA22: 1 | BC22: Roger Johnson | BD22: CB | BE22: 2014-2016 | BF22: 23 | BG22: 0 | BH22: 2009-2010 | BI22: 76 | BJ22: 2 | BL22: Tony Watt | BM22: ST | BN22: 2014-2017 | BO22: 56 | BP22: 10 | BQ22: 2015 | BR22: 11 | BS22: 2 | BU22: Jamie Mascoll | BV22: LB | BW22: 2018 | BX22: 1 | BY22: 0 | BZ22: 2020 | CA22: 7 | CB22: 0 | CD22: Kelly Youga | CE22: LB | CF22: 2007-2009 | CG22: 62 | CH22: 1 | CI22: 2005 | CJ22: 4 | CK22: 0 | CV22: Deji Oshilaja | CW22: CB | CX22: 2019-2020 | CY22: 46 | CZ22: 1 | DA22: 2014-2015 | DB22: 1 | DC22: 0 | DE22: Danny Mills | DF22: RB | DG22: 1997-2007 | DH22: 64 | DI22: 3 | DJ22: 2007 | DK22: 2 | DL22: 0 | DN22: Isaac Olaofe | DO22: ST | DP22: 2025 | DQ22: 25 | DR22: 1 | DS22: 2022 | DT22: 3 | DU22: 0 | EF22: Miloš Veljković | EG22: CB | EH22: 2014 | EI22: 3 | EJ22: 0 | EK22: 2014 | EL22: 4 | EM22: 0 | EO22: Declan Rudd | EP22: GK | EQ22: 2016 | ER22: 40 | ES22: 0 | ET22: 2009-2015 | EU22: 26 | EV22: 0 | EX22: Saša Ilić | EY22: GK | EZ22: 1997-2000 | FA22: 51 | FB22: 0 | FC22: 2001 | FD22: 7 | FE22: 0 | FG22: Kyel Reid | FH22: LW | FI22: 2009-2010 | FJ22: 49 | FK22: 5 | FL22: 2014-2015 | FM22: 23 | FN22: 0 | FP22: Robert Hulse | FQ22: ST | FR22: 2012 | FS22: 15 | FT22: 3 | FU22: 2010-2011 | FV22: 23 | FW22: 2 | GH22: Mike Small | GI22: ST | GJ22: 1993 | GK22: 2 | GL22: 0 | GM22: 1993 | GN22: 3 | GO22: 1
A23: Scott Minto | B23: LB | C23: 1992-1993 | D23: 78 | E23: 3 | F23: 1998-2002 | G23: 51 | H23: 0 | J23: Ben Watson | K23: CM | L23: 2020-2021 | M23: 40 | N23: 1 | O23: 2014-2017 | P23: 78 | Q23: 2 | AK23: Bradley Wright-Phillips | AL23: ST | AM23: 2010-2012 | AN23: 82 | AO23: 31 | AP23: 2006-2008 | AQ23: 111 | AR23: 22 | AT23: Alan McLeary | AU23: CB | AV23: 1992-1995 | AW23: 66 | AX23: 3 | AY23: 1992 | AZ23: 3 | BA23: 0 | BC23: Jonathan Leko | BD23: LW, RW, ST | BE23: 2019-2021 | BF23: 48 | BG23: 7 | BH23: 2020-2022 | BI23: 50 | BJ23: 1 | BU23: Paddy McCarthy | BV23: CB | BW23: 2007 | BX23: 29 | BY23: 2 | BZ23: 2014 | CA23: 5 | CB23: 0 | CV23: Dillon Phillips | CW23: GK | CX23: 2014-2019 | CY23: 90 | CZ23: 0 | DA23: 2020-2021 | DB23: 36 | DC23: 0 | DE23: Chris Powell | DF23: LB | DG23: 1998-2007 | DH23: 244 | DI23: 2 | DJ23: 1995-1997 | DK23: 91 | DL23: 1 | DN23: Therry Racon | DO23: CM | DP23: 2007-2010 | DQ23: 98 | DR23: 7 | DS23: 2012 | DT23: 1 | DU23: 0 | EF23: Rhys Williams | EG23: CB | EH23: 2015 | EI23: 4 | EJ23: 0 | EK23: 2009-2014 | EL23: 126 | EM23: 5 | EO23: Darel Russell | EP23: CDM | EQ23: 2011 | ER23: 11 | ES23: 2 | ET23: 1997-2009 | EU23: 244 | EV23: 18 | EX23: Dean Kiely | EY23: GK | EZ23: 1999-2005 | FA23: 222 | FB23: 0 | FC23: 2005 | FD23: 15 | FE23: 0 | FG23: Declan Rudd | FH23: GK | FI23: 2016 | FJ23: 40 | FK23: 0 | FL23: 2012-2021 | FM23: 187 | FN23: 0 | FP23: Carl Ikeme | FQ23: GK | FR23: 2009 | FS23: 4 | FT23: 0 | FU23: 2009 | FV23: 17 | FW23: 0 | GH23: Terry Taylor | GI23: CM | GJ23: 2023-2024 | GK23: 16 | GL23: 0 | GM23: 2019-2020 | GN23: 11 | GO23: 1
A24: Shaun Newton | B24: RM | C24: 1992-2000 | D24: 240 | E24: 20 | F24: 2004-2006 | G24: 64 | H24: 2 | AT24: Izale McLeod | AU24: ST | AV24: 2007-2009 | AW24: 31 | AX24: 3 | AY24: 2003 | AZ24: 7 | BA24: 0 | BC24: Leroy Lita | BD24: ST | BE24: 2007 | BF24: 8 | BG24: 3 | BH24: 2012 | BI24: 10 | BJ24: 3 | BU24: Erhun Oztumer | BV24: CAM | BW24: 2019-2020 | BX24: 18 | BY24: 0 | BZ24: 2018-2019 | CA24: 19 | CB24: 1 | CV24: John Robinson | CW24: RM | CX24: 1992-2002 | CY24: 332 | CZ24: 36 | DA24: 2003 | DB24: 34 | DC24: 2 | DE24: Gary Rowett | DF24: RB | DG24: 2002-2003 | DH24: 13 | DI24: 1 | DJ24: 1995-1997 | DK24: 105 | DL24: 2 | DN24: Martyn Waghorn | DO24: ST | DP24: 2008 | DQ24: 7 | DR24: 1 | DS24: 2013 | DT24: 14 | DU24: 3 | EF24: Luke Young | EG24: RB | EH24: 2001-2006 | EI24: 187 | EJ24: 4 | EK24: 2007 | EL24: 35 | EM24: 1 | EO24: Kevin Scott | EP24: CB | EQ24: 1996 | ER24: 4 | ES24: 0 | ET24: 1996-1999 | EU24: 33 | EV24: 0 | EX24: Craig MacGillivray | EY24: GK | EZ24: 2021-2022 | FA24: 49 | FB24: 0 | FC24: 2018-2020 | FD24: 126 | FE24: 0 | FG24: Darel Russell | FH24: CDM | FI24: 2011 | FJ24: 11 | FK24: 2 | FL24: 2010-2011 | FM24: 27 | FN24: 0 | FP24: Matt Jackson | FQ24: CB | FR24: 1995 | FS24: 8 | FT24: 0 | FU24: 1996 | FV24: 7 | FW24: 0 | GH24: Darren Ward | GI24: CB | GJ24: 2008 | GK24: 16 | GL24: 0 | GM24: 2007-2008 | GN24: 31 | GO24: 0
A25: Frank Nouble | B25: ST | C25: 2010 | D25: 9 | E25: 1 | F25: 2009-2011 | G25: 13 | H25: 1 | AT25: Jesurun Rak Sakyi | AU25: RW | AV25: 2022 | AW25: 49 | AX25: 15 | AY25: 2024 | AZ25: 35 | BA25: 7 | BC25: Alfie May | BD25: ST | BE25: 2023 | BF25: 47 | BG25: 25 | BH25: 2024 | BI25: 49 | BJ25: 16 | BU25: Darren Pratley | BV25: CM | BW25: 2018-2020 | BX25: 107 | BY25: 5 | BZ25: 2011-2017 | CA25: 189 | CB25: 16 | CV25: Jamie Ward | CW25: ST | CX25: 2018 | CY25: 10 | CZ25: 1 | DA25: 2017 | DB25: 4 | DC25: 0 | DE25: Mathias Svensson | DF25: ST | DG25: 1999-2003 | DH25: 70 | DI25: 7 | DJ25: 2003 | DK25: 10 | DL25: 3 | DN25: Darren Ward | DO25: CB | DP25: 2008 | DQ25: 16 | DR25: 0 | DS25: 2001-2012 | DT25: 237 | DU25: 6 | EO25: Oliver Skipp | EP25: CM | EQ25: 2026- | ER25: 1* | ES25: 0* | ET25: 2020-2021 | EU25: 45 | EV25: 1 | EX25: Tom McIntyre | EY25: CB | EZ25: 2024 | FA25: 10 | FB25: 0 | FC25: 2023-2024 | FD25: 14 | FE25: 0 | FG25: Scott Sinclair | FH25: LW, RW | FI25: 2007 | FJ25: 3 | FK25: 0 | FL25: 2019-2021 | FM25: 85 | FN25: 14 | FP25: Todd Kane | FQ25: RB | FR25: 2022 | FS25: 5 | FT25: 0 | FU25: 2019-2020 | FV25: 65 | FW25: 3 | GH25: Michał Żyro | GI25: ST | GJ25: 2017 | GK25: 13 | GL25: 3 | GM25: 2015-2017 | GN25: 15 | GO25: 3
A26: Scott Parker | B26: CM | C26: 1997-2003 | D26: 128 | E26: 9 | F26: 2007-2011 | G26: 113 | H26: 10 | AT26: Andy Reid | AU26: CAM | AV26: 2006-2007 | AW26: 38 | AX26: 8 | AY26: 2010 | AZ26: 9 | BA26: 2 | BC26: Michael Morrison | BD26: CB | BE26: 2011-2014 | BF26: 138 | BG26: 6 | BH26: 2014-2018 | BI26: 183 | BJ26: 14 | BU26: John Salako | BV26: CM | BW26: 1999-2001 | BX26: 46 | BY26: 2 | BZ26: 1997 | CA26: 7 | CB26: 0 | CV26: Tony Watt | CW26: ST | CX26: 2014-2017 | CY26: 56 | CZ26: 10 | DA26: 2015 | DB26: 9 | DC26: 2 | DE26: Andy Todd | DF26: CB | DG26: 1999-2001 | DH26: 40 | DI26: 1 | DJ26: 2007-2008 | DK26: 30 | DL26: 1 | DN26: Josh Wright | DO26: CM | DP26: 2008 | DQ26: 2 | DR26: 0 | DS26: 2011-2014 | DT26: 47 | DU26: 1 | EO26: Graham Stuart | EP26: CM | EQ26: 1998-2004 | ER26: 148 | ES26: 21 | ET26: 2004 | EU26: 8 | EV26: 0 | EX26: Izale McLeod | EY26: ST | EZ26: 2007-2009 | FA26: 31 | FB26: 3 | FC26: 2012 | FD26: 24 | FE26: 10 | FG26: Akpo Sodje | FH26: ST | FI26: 2009-2010 | FJ26: 40 | FK26: 5 | FL26: 2012 | FM26: 14 | FN26: 4 | FP26: Charlie Kelman | FQ26: ST | FR26: 2025 | FS26: 36 | FT26: 7 | FU26: 2020-2023 | FV26: 26 | FW26: 0
A27: Dan Potts | B27: LB | C27: 2024 | D27: 1 | E27: 0 | F27: 2011-2014 | G27: 6 | H27: 0 | AT27: Kyel Reid | AU27: LM | AV27: 2009-2010 | AW27: 49 | AX27: 5 | AY27: 2009 | AZ27: 7 | BA27: 0 | BC27: Thomas Myhre | BD27: GK | BE27: 2005-2006 | BF27: 21 | BG27: 0 | BH27: 1999 | BI27: 7 | BJ27: 0 | BU27: Marvin Sordell | BV27: ST | BW27: 2013 | BX27: 31 | BY27: 7 | BZ27: 2011-2012 | CA27: 25 | CB27: 4 | CV27: Jonny Williams | CW27: CAM | CX27: 2018-2020 | CY27: 63 | CZ27: 2 | DA27: 2020 | DB27: 9 | DC27: 0 | DE27: Marcus Tudgay | DF27: ST | DG27: 2013 | DH27: 2 | DI27: 0 | DJ27: 2002-2004 | DK27: 71 | DL27: 15 | EO27: Mathias Svensson | EP27: ST | EQ27: 1999-2003 | ER27: 70 | ES27: 7 | ET27: 2003-2004 | EU27: 42 | EV27: 11 | EX27: Michael Morrison | EY27: CB | EZ27: 2011-2014 | FA27: 138 | FB27: 6 | FC27: 2022 | FD27: 25 | FE27: 0 | FG27: Connor Wickham | FH27: ST | FI27: 2023 | FJ27: 4 | FK27: 1 | FL27: 2021 | FM27: 2 | FN27: 0 | FP27: Carl Leaburn | FQ27: ST | FR27: 1992-1997 | FS27: 203 | FT27: 38 | FU27: 2001 | FV27: 1 | FW27: 0
A28: Diego Poyet | B28: CM | C28: 2013-2015 | D28: 27 | E28: 0 | F28: 2014-2015 | G28: 5 | H28: 0 | AT28: Matthew Spring | AU28: CM | AV28: 2008-2009 | AW28: 25 | AX28: 2 | AY28: 2008 | AZ28: 11 | BA28: 1 | BC28: Ricky Otto | BD28: LW | BE28: 1996 | BF28: 7 | BG28: 0 | BH28: 1994-1997 | BI28: 46 | BJ28: 6 | BU28: Andy Todd | BV28: CB | BW28: 1999-2001 | BX28: 40 | BY28: 1 | BZ28: 1995-1999 | CA28: 84 | CB28: 2 | DE28: Martyn Waghorn | DF28: ST | DG28: 2008 | DH28: 7 | DI28: 1 | DJ28: 2018-2023 | DK28: 148 | DL28: 37 | EX28: Yassin Moutaouakil | EY28: RB | EZ28: 2007-2008 | FA28: 21 | FB28: 0 | FC28: 2012-2013 | FD28: 32 | FE28: 0 | FP28: Kevin Lisbie | FQ28: ST | FR28: 1996-2006 | FS28: 155 | FT28: 16 | FU28: 2000 | FV28: 2 | FW28: 0
A29: Darren Randolph | B29: GK | C29: 2006-2009 | D29: 14 | E29: 0 | F29: 2015-2022 | G29: 47 | H29: 0 | AT29: Lyle Taylor | AU29: ST | AV29: 2018-2019 | AW29: 64 | AX29: 35 | AY29: 2013 | AZ29: 20 | BA29: 2 | BC29: Gary Poole | BD29: RB | BE29: 1996-1997 | BF29: 16 | BG29: 1 | BH29: 1994-1996 | BI29: 72 | BJ29: 0 | BU29: Ricardo Vaz Tê | BV29: ST | BW29: 2015 | BX29: 12 | BY29: 0 | BZ29: 2003-2008 | CA29: 63 | CB29: 3 | DE29: Jamie Ward | DF29: ST | DG29: 2018 | DH29: 10 | DI29: 1 | DJ29: 2010-2014 | DK29: 142 | DL29: 34 | EX29: Andy Petterson | EY29: GK | EZ29: 1994-1999 | FA29: 72 | FB29: 0 | FC29: 1998-2000 | FD29: 32 | FE29: 0 | FP29: Kazenga LuaLua | FQ29: LW | FR29: 2023 | FS29: 4 | FT29: 0 | FU29: 2016-2017 | FV29: 19 | FW29: 1
A30: Kyel Reid | B30: LW | C30: 2009-2010 | D30: 49 | E30: 5 | F30: 2005-2007 | G30: 3 | H30: 0 | AT30: Carl Tiler | AU30: CB | AV30: 1998-2000 | AW30: 45 | AX30: 2 | AY30: 1996-1997 | AZ30: 23 | BA30: 2 | BC30: Darren Randolph | BD30: GK | BE30: 2006-2009 | BF30: 14 | BG30: 0 | BH30: 2013-2014 | BI30: 92 | BJ30: 0 | BU30: Lawrie Wilson | BV30: RM, RB | BW30: 2012-2014 | BX30: 99 | BY30: 6 | BZ30: 2015-2016 | CA30: 36 | CB30: 2 | DE30: Conor Washington | DF30: ST | DG30: 2020-2021 | DH30: 75 | DI30: 22 | DJ30: 2023-2024 | DK30: 25 | DL30: 4 | EX30: Joe Pigott | EY30: ST | EZ30: 2013-2014 | FA30: 13 | FB30: 0 | FC30: 2022 | FD30: 39 | FE30: 6 | FP30: Josh Parker | FQ30: ST | FR30: 2018 | FS30: 10 | FT30: 0 | FU30: 2009-2010 | FV30: 5 | FW30: 0
A31: Mark Robson | B31: LW | C31: 1993-1996 | D31: 105 | E31: 9 | F31: 1992-1993 | G31: 47 | H31: 8 | AT31: Jamie Ward | AU31: ST | AV31: 2018 | AW31: 10 | AX31: 1 | AY31: 2008-2010 | AZ31: 63 | BA31: 9 | BC31: Gary Rowett | BD31: RB | BE31: 2002-2003 | BF31: 13 | BG31: 1 | BH31: 1998-2000 | BI31: 87 | BJ31: 6 | DE31: Louie Watson | DF31: CM | DG31: 2023 | DH31: 23 | DI31: 0 | DJ31: 2020-2021 | DK31: 40 | DL31: 2 | EX31: Dan Potts | EY31: LB | EZ31: 2024 | FA31: 1 | FB31: 0 | FC31: 2013 | FD31: 5 | FE31: 0 | FP31: Gavin Peacock | FQ31: CM | FR31: 2001 | FS31: 5 | FT31: 0 | FU31: 1996-2001 | FV31: 190 | FW31: 35
A32: Mike Small | B32: ST | C32: 1993 | D32: 2 | E32: 0 | F32: 1992 | G32: 9 | H32: 0 | AT32: Conor Washington | AU32: ST | AV32: 2020-2021 | AW32: 75 | AX32: 22 | AY32: 2018 | AZ32: 16 | BA32: 0 | BC32: Andrew Shinnie | BD32: CM | BE32: 2020 | BF32: 29 | BG32: 3 | BH32: 2013-2016 | BI32: 71 | BJ32: 5 | DE32: Simon Webster | DF32: CB | DG32: 1992-1993 | DH32: 43 | DI32: 2 | DJ32: 1995 | DK32: 3 | DL32: 0 | EX32: Lee Power | EY32: ST | EZ32: 1992 | FA32: 5 | FB32: 0 | FC32: 1993 | FD32: 2 | FE32: 0 | FP32: Simon Royce | FQ32: GK | FR32: 1998-2003 | FS32: 9 | FT32: 0 | FU32: 2002-2006 | FV32: 79 | FW32: 0
A33: Alexandre Song | B33: CDM | C33: 2006 | D33: 12 | E33: 0 | F33: 2014-2015 | G33: 46 | H33: 0 | BC33: Scott Sinclair | BD33: LW, RW | BE33: 2007 | BF33: 3 | BG33: 0 | BH33: 2008 | BI33: 14 | BJ33: 0 | EX33: Linvoy Primus | EY33: CB | EZ33: 1992-2008 | FA33: 14 | FB33: 1 | FC33: 2000-2008 | FD33: 198 | FE33: 5 | FP33: Scott Sinclair | FQ33: LW, RW | FR33: 2007 | FS33: 3 | FT33: 0 | FU33: 2007 | FV33: 9 | FW33: 1
A34: Jonathan Spector | B34: CB, RB | C34: 2005 | D34: 20 | E34: 0 | F34: 2006-2010 | G34: 102 | H34: 1 | BC34: Jonathan Spector | BD34: RB, CB | BE34: 2005 | BF34: 20 | BG34: 0 | BH34: 2011-2016 | BI34: 166 | BJ34: 0 | EX34: Therry Racon | EY34: CM | EZ34: 2007-2010 | FA34: 98 | FB34: 7 | FC34: 2012-2013 | FD34: 31 | FE34: 0 | FP34: Matthew Smith | FQ34: CAM | FR34: 2019 | FS34: 2 | FT34: 0 | FU34: 2019 | FV34: 10 | FW34: 0
